Workbook

Sheet Results
A1: Submission ID | B1: Last updated | C1: Submission started | D1: Status | E1: Current step | F1: How would you characterize your professional background on a scale from academic to industrial? | G1: Have you been involved in the design of an NLP4RE tool? | H1: Have you been involved in the implementation of an NLP4RE tool? | I1: Have you participated in the AIRE’25 joint activity? | J1: How many of the NLP4RE tools you have been involved in the design or implementation of are still actively maintained (i.e., they receive regular updates such as bug fixes, dependency upgrades, or new features)? | K1: When you designed or implemented an NLP4RE tool, did you reuse any existing components of other tools (excluding libraries)? | L1: Learning to apply the SRA would be easy for me. | M1: I would find it easy to get the information I need out of the SRA. | N1: My interaction with the SRA would be clear and understandable. | O1: I would find SRA to be flexible to interact with. | P1: It would be easy for me to become skillful at using the SRA. | Q1: I would find the SRA easy to use. | R1: Using the SRA for developing a new NLP4RE tool would enable me to accomplish tasks more quickly. | S1: Using the SRA would improve my performance when developing an NLP4RE tool. | T1: Using the SRA when developing a new NLP4RE tool would increase my productivity. | U1: Using the SRA would enhance my effectiveness when developing a new NLP4RE tool. | V1: Using the SRA would make it easier to develop a new NLP4RE tool. | W1: I would find the SRA useful for developing a new NLP4RE tool. | X1: I intend to use the SRA when developing an NLP4RE tool in the future. | Y1: I intend to recommend colleagues, students, or others to use the SRA when developing a new NLP4RE tool. | Z1: I intend to re-implement an existing NLP4RE tool using the SRA. | AA1: It will cost less effort to re-use components from NLP4RE tools that adhere to the SRA than from comparable NLP4RE tools not adhering to it. | AB1: An NLP4RE tool that adheres to the SRA is applicable to more use cases (e.g., different types of input documents) than comparable NLP4RE tools that do not adhere to it. | AC1: An NLP4RE tool that adheres to the SRA is easier to compare with other tools that perform a similar task (e.g., requirements classification), than comparable NLP4RE tools that do not adhere to it. | AD1: An NLP4RE tool that adheres to the SRA is easier to maintain than comparable NLP4RE tools that do not adhere to it. | AE1: What benefits of the SRA do you perceive that have not been mentioned yet? | AF1: What drawbacks or challenges of the SRA do you perceive that have not been mentioned yet? | AG1: Please provide any additional feedback not covered in the previous questions. | AH1: Errors | AI1: Url | AJ1: Network ID | AK1: Network ID
A2: f8662a56-31ea-4aef-915a-84f3d36fc0b7 | B2: Fri Feb 20 2026 09:56:00 GMT+0100 (hora estándar de Europa central) | C2: Tue Feb 17 2026 09:30:00 GMT+0100 (hora estándar de Europa central) | D2: finished | E2: Ending | F2: 2 | G2: Yes | H2: Yes | I2: No | J2: None | K2: Yes | L2: 5 | M2: 4 | N2: 6 | O2: 6 | P2: 6 | Q2: 6 | R2: 6 | S2: 5 | T2: 5 | U2: 5 | V2: 5 | W2: 6 | X2: 4 | Y2: 4 | Z2: 5 | AA2: 7 | AB2: 7 | AC2: 7 | AD2: 7 | AE2: It is a common structure for other tools, and the main utility would be the possiblity of plugging and playing novel components as novel needs emerge. | AF2: requirements is more and more intertwined with other software process phases, so having an architecture only for NLP4RE looks a bit outdated. | AG2: I think that part of the architecture is not much different from what you have with tools such as GATE (the pipeline view, especially), so the specificity of requirements and the software world needs to be better characterised. Also, it is not clear how the architecture addresses the hairyness of requirements tasks, the way they are intertwined, and the different needs of different companies. AS A SIDE NOTE: note that a questionnaire like that suffers from systematic response bias!!! | AH2: None | AI2: https://build.fillout.com/editor/jmGtx5dRm2us/results?sessionId=f8662a56-31ea-4aef-915a-84f3d36fc0b7 | AJ2: 1ce7247551604dfff9455f8b4dfc913b
A3: e002e40f-9df0-4253-8f9b-8f62f2818b1a | B3: Thu Feb 19 2026 08:12:00 GMT+0100 (hora estándar de Europa central) | C3: Thu Feb 19 2026 07:36:00 GMT+0100 (hora estándar de Europa central) | D3: finished | E3: Ending | F3: 3 | G3: Yes | H3: No | I3: No | J3: Few | K3: No | L3: 4 | M3: 6 | N3: 6 | O3: 6 | P3: 4 | Q3: 6 | R3: 6 | S3: 6 | T3: 6 | U3: 6 | V3: 6 | W3: 6 | X3: 6 | Y3: 6 | Z3: 5 | AA3: 4 | AB3: 4 | AC3: 6 | AD3: 5 | AE3: I think the likert scale questions pretty much cover them all | AF3: Glad that you are seeking this information, complexity of the approach and details need more time to digest and undertsnad. would recommend hosting workshops/meetings to explain the work first | AH3: None | AI3: https://build.fillout.com/editor/jmGtx5dRm2us/results?sessionId=e002e40f-9df0-4253-8f9b-8f62f2818b1a | AJ3: 8d222884e4bdddae480f8b5440cdde1b
A4: 04f46aeb-4a37-4b3e-9c58-b5b261307f08 | B4: Sun Feb 15 2026 13:03:00 GMT+0100 (hora estándar de Europa central) | C4: Sun Feb 15 2026 12:21:00 GMT+0100 (hora estándar de Europa central) | D4: finished | E4: Ending | F4: 2 | G4: Yes | H4: Yes | I4: Yes | J4: None | K4: I don't know | L4: 4 | M4: 4 | N4: 4 | O4: 4 | P4: 4 | Q4: 4 | R4: 5 | S4: 4 | T4: 5 | U4: 4 | V4: 5 | W4: 5 | X4: 5 | Y4: 4 | Z4: 4 | AA4: 5 | AB4: 4 | AC4: 6 | AD4: 4 | AE4: It would be useful to have it as a starting point | AF4: Making it useful and understandable for novices | AG4: Page 2 in the document refers to Figure 1. I think this should be Figure 2 | AH4: None | AI4: https://build.fillout.com/editor/jmGtx5dRm2us/results?sessionId=04f46aeb-4a37-4b3e-9c58-b5b261307f08 | AJ4: 3873cefcad38f9ac6e1a42c9b06c696a
A5: 9d8f2b70-03d6-4c72-924b-7ab2c56fb390 | B5: Wed Feb 11 2026 13:33:00 GMT+0100 (hora estándar de Europa central) | C5: Wed Feb 11 2026 13:26:00 GMT+0100 (hora estándar de Europa central) | D5: finished | E5: Ending | F5: 3 | G5: Yes | H5: Yes | I5: No | J5: All | K5: No | L5: 5 | M5: 3 | N5: 4 | O5: 5 | P5: 4 | Q5: 6 | R5: 6 | S5: 6 | T5: 6 | U5: 7 | V5: 6 | W5: 7 | X5: 5 | Y5: 5 | Z5: 2 | AA5: 7 | AB5: 7 | AC5: 7 | AD5: 6 | AE5: - | AF5: Now the description is a very high level of abstraction | AH5: None | AI5: https://build.fillout.com/editor/jmGtx5dRm2us/results?sessionId=9d8f2b70-03d6-4c72-924b-7ab2c56fb390 | AJ5: b5afa00de171ecddd13f6e7497b4c8bd | AK5: 3c006a3576fbc0954dc2db5414f4a467
A6: 6c478c68-910a-4f63-b412-bdfb90b9e639 | B6: Tue Feb 10 2026 12:52:00 GMT+0100 (hora estándar de Europa central) | C6: Tue Feb 10 2026 09:12:00 GMT+0100 (hora estándar de Europa central) | D6: finished | E6: Ending | F6: 1 | G6: Yes | H6: Yes | I6: No | J6: Few | K6: No | L6: 3 | M6: 5 | N6: 5 | O6: 5 | P6: 5 | Q6: 5 | R6: 6 | S6: 5 | T6: 5 | U6: 5 | V6: 5 | W6: 5 | X6: 5 | Y6: 4 | Z6: 2 | AA6: 6 | AB6: 5 | AC6: 7 | AD6: 7 | AE6: Tool maintenance and upgradation is expected to significantly improve if everyone in the RE community starts using SRA. | AF6: Reimplementing existing tools using SRA would be challenging. Moreover, researchers and practitioners need some training or tutorials to fully understand how to use SRA for developing effective and efficient toolsets for RE. | AH6: None | AI6: https://build.fillout.com/editor/jmGtx5dRm2us/results?sessionId=6c478c68-910a-4f63-b412-bdfb90b9e639 | AJ6: 63e6a88c3b97f446cab0b099e810a6d9 | AK6: 15018a4a3e8496b90f5c5bb3e179f383
A7: 8f2270dc-49b4-40d8-ad01-84ad5e604450 | B7: Tue Feb 10 2026 09:30:00 GMT+0100 (hora estándar de Europa central) | C7: Tue Feb 10 2026 08:57:00 GMT+0100 (hora estándar de Europa central) | D7: finished | E7: Ending | F7: 4 | G7: Yes | H7: Yes | I7: No | J7: Few | K7: Yes | L7: 4 | M7: 5 | N7: 5 | O7: 5 | P7: 4 | Q7: 4 | R7: 4 | S7: 3 | T7: 4 | U7: 3 | V7: 4 | W7: 4 | X7: 4 | Y7: 4 | Z7: 1 | AA7: 3 | AB7: 4 | AC7: 2 | AD7: 3 | AE7: Some of the components may be used also in other contexts - independent of whether they use NLP or not. | AF7: The architecture is very rough. If you really want to generate benefits, then the architecture specification needs to be much more detailled. E.g. the AUTOSAR specification is many hundred pages long - without such a detailled specification, you get many tools that adhere to a similar architecture, but you cannot work together. What I understood in the mail is that the goal is to better work together, and e.g. easily extend with other processors, or switch to another logger. If this is the goal, the interfaces need to be very specific. When I think of the amount of work spent on AUTOSAR, I am not sure whether this would pay off in a NLP4RE context. It may in academic context (as business is not that relevant, instead working together might be more relevant), but for tool vendors I am not so sure. | AG7: With the new agent technology rising, I am not sure whether a whole new concept is needed. There are now LLMs that combine formal reasoning with Natural language - and I see that most of my colleagues prefer heuristic findings, that are easy to understand, to correct findings, that are difficult to understand. ... and most of them find formal methods difficult to understand. In my eyes the architecture proposed will mainly benefit complex analysis methods, and making maintainable tools that do that - but my hope is that agents will abstract that away from the users. If we say that the agent is working in the presentation layer as explainability manager, and also does the orchestration in the service layer, this might work - but as it gets so fast to build agents, we should check first whether it would be faster and cheaper to have different agents on different architectures, than to try to harmonize architectures. One small point: In the data layer I would make an explicit component that stores the used models. This also has to be under configuration management. | AH7: None | AI7: https://build.fillout.com/editor/jmGtx5dRm2us/results?sessionId=8f2270dc-49b4-40d8-ad01-84ad5e604450 | AJ7: 935e7e79f2deed22776a72a998fc22dc | AK7: ff98f630f2d71112c15e926b4e220f02
A8: c190122f-b381-49e6-8cdb-7824bc46ce0a | B8: Mon Feb 09 2026 18:26:00 GMT+0100 (hora estándar de Europa central) | C8: Mon Feb 09 2026 18:01:00 GMT+0100 (hora estándar de Europa central) | D8: finished | E8: Ending | F8: 2 | G8: Yes | H8: Yes | I8: No | J8: None | K8: Yes | L8: 5 | M8: 5 | N8: 5 | O8: 5 | P8: 4 | Q8: 5 | R8: 6 | S8: 6 | T8: 6 | U8: 6 | V8: 6 | W8: 7 | X8: 5 | Y8: 6 | Z8: 3 | AA8: 6 | AB8: 7 | AC8: 6 | AD8: 6 | AE8: The SRA’s potential as a shared vocabulary and conceptual baseline for the NLP4RE community. | AF8: One challenge is the abstraction gap between the reference architecture and concrete implementations. While the SRA is intentionally technology agnostic, less experienced teams may struggle to translate architectural components into concrete design and code decisions without additional guidance, examples, or reference implementations. | AG8: The SRA is clearly motivated, well structured, and aligned with recurring problems in NLP4RE tool development. To further increase its practical adoption, future iterations could include illustrative instantiations of the architecture, mapping existing tools to AIRERA components, or providing lightweight compliance guidelines for different development contexts. | AH8: None | AI8: https://build.fillout.com/editor/jmGtx5dRm2us/results?sessionId=c190122f-b381-49e6-8cdb-7824bc46ce0a | AJ8: a82daa6036e755a0f9762a323247243c | AK8: a1699c34d1e61abae41a913867efe44a
A9: 660a2d0f-dd7b-48d4-a25a-fd1574fd03d2 | B9: Sat Feb 07 2026 09:43:00 GMT+0100 (hora estándar de Europa central) | C9: Sat Feb 07 2026 09:34:00 GMT+0100 (hora estándar de Europa central) | D9: finished | E9: Ending | F9: 2 | G9: Yes | H9: No | I9: No | J9: Few | K9: Yes | L9: 6 | M9: 7 | N9: 6 | O9: 6 | P9: 6 | Q9: 6 | R9: 7 | S9: 7 | T9: 6 | U9: 6 | V9: 6 | W9: 7 | X9: 7 | Y9: 7 | Z9: 4 | AA9: 7 | AB9: 4 | AC9: 6 | AD9: 6 | AE9: I think that the comparability (and to some extent reproducibility) of what is being developed would be strengthened a lot, next to reducing the barrier for engagement in the NLP community | AF9: I was very intrigued by the explainability component but felt that it was a bit hard to judge what impact it will exactly have. I certainly understand that it is too soon to tell, but I am very curious to see it in action some day :) | AG9: Kudos! | AH9: None | AI9: https://build.fillout.com/editor/jmGtx5dRm2us/results?sessionId=660a2d0f-dd7b-48d4-a25a-fd1574fd03d2 | AJ9: b98b6eb38dda53099ced0a2521c9fe6f | AK9: 3f8cbb6a92073e62c6e336ae8d228981
A10: 6c833749-ced3-4186-b6ad-b9e43ec3e9ad | B10: Fri Feb 06 2026 16:11:00 GMT+0100 (hora estándar de Europa central) | C10: Fri Feb 06 2026 15:16:00 GMT+0100 (hora estándar de Europa central) | D10: finished | E10: Ending | F10: 1 | G10: Yes | H10: Yes | I10: No | J10: Few | K10: No | L10: 3 | M10: 5 | N10: 4 | O10: 2 | P10: 4 | Q10: 4 | R10: 6 | S10: 6 | T10: 4 | U10: 4 | V10: 5 | W10: 6 | X10: 5 | Y10: 5 | Z10: 4 | AA10: 7 | AB10: 4 | AC10: 6 | AD10: 7 | AE10: I can't think of any further benefits except those already explicitly mentioned | AF10: - "Learnability": How well does the SRA cater tools or models that "learn" from user feedback? I am particularly thinking of applications where there is no definitive ground-truht, which are highly context-dependent, and render "universal" tools as ineffective. In other words, tools that invite human responses, e.g., about accepting / rejecting suggestions, so that the tool can iteratively learn from this feedback. I am not sure whether the SRA like this facilitates the storing of past user actions/decisions/feedback, so that tools can adapt and "learn". - Language: Is language support something that you want to consider or not? Is the SRA agnostic of language choice or does it support multiple languages? | AH10: None | AI10: https://build.fillout.com/editor/jmGtx5dRm2us/results?sessionId=6c833749-ced3-4186-b6ad-b9e43ec3e9ad | AJ10: a283104491d98c22e40434370fec8929 | AK10: e04062cc7745d247dd82a11ebc3eebb9
A11: daecc691-485c-43f9-ad11-6461785398fa | B11: Fri Feb 06 2026 13:57:00 GMT+0100 (hora estándar de Europa central) | C11: Fri Feb 06 2026 13:45:00 GMT+0100 (hora estándar de Europa central) | D11: finished | E11: Ending | F11: 3 | G11: Yes | H11: Yes | I11: No | J11: Few | K11: Yes | L11: 5 | M11: 4 | N11: 4 | O11: 5 | P11: 5 | Q11: 4 | R11: 5 | S11: 5 | T11: 4 | U11: 5 | V11: 5 | W11: 5 | X11: 4 | Y11: 5 | Z11: 3 | AA11: 6 | AB11: 4 | AC11: 4 | AD11: 6 | AE11: Having a standard architecture that, if adopted in NLP4RE research, would make it easier to experiment with the tools. Now it takes way too much time (in replication and experimentation) to understand what "hacks" people use in their tools to get them running. I like this layered SoA SRA, which could decouple most of the components, which definitely helps with reuse and reduces complexity. | AF11: I believe it will be a hard sell. There are several other approaches, like the spaCy piping, etc., that people fail to use. It would not surprise me if it is hard to push real use of SRA to people. | AH11: None | AI11: https://build.fillout.com/editor/jmGtx5dRm2us/results?sessionId=daecc691-485c-43f9-ad11-6461785398fa | AJ11: 07cbb83f2f7ec46082089843ee54d2cf | AK11: c12807df1ad67a07aee3f9092ddf3251
A12: bb1cee3d-3225-4d28-b25d-0677ea62cb17 | B12: Thu Feb 05 2026 10:51:00 GMT+0100 (hora estándar de Europa central) | C12: Thu Feb 05 2026 10:28:00 GMT+0100 (hora estándar de Europa central) | D12: finished | E12: Ending | F12: 1 | G12: Yes | H12: Yes | I12: No | J12: None | K12: No | L12: 6 | M12: 6 | N12: 6 | O12: 4 | P12: 6 | Q12: 6 | R12: 7 | S12: 7 | T12: 7 | U12: 7 | V12: 7 | W12: 7 | X12: 5 | Y12: 6 | Z12: 2 | AA12: 7 | AB12: 6 | AC12: 7 | AD12: 5 | AE12: None | AF12: I appreciate the work that has been reportedly done to review existing NLP4RE tools, and thus produce an SRA that is grounded in the existing architectures. However, this makes a pretty big assumption about the future landscape of NLP4RE tools, which are currently going through a major revolution with LLMs and similar technologies/tools. I'm not sure how applicable such a framework will be in 2-5 years with such incoming changes. | AH12: None | AI12: https://build.fillout.com/editor/jmGtx5dRm2us/results?sessionId=bb1cee3d-3225-4d28-b25d-0677ea62cb17 | AJ12: f869df5a154fa3ce9684435b264fcbd5 | AK12: b7f91ee0bd0712b0dd52f152ce988f66
A13: a75278c1-c512-412a-b9f6-3c716831b733 | B13: Wed Feb 04 2026 11:52:00 GMT+0100 (hora estándar de Europa central) | C13: Wed Feb 04 2026 11:37:00 GMT+0100 (hora estándar de Europa central) | D13: finished | E13: Ending | F13: 4 | G13: Yes | H13: Yes | I13: No | J13: None | K13: Yes | L13: 5 | M13: 4 | N13: 4 | O13: 6 | P13: 2 | Q13: 3 | R13: 6 | S13: 5 | T13: 6 | U13: 6 | V13: 7 | W13: 6 | X13: 5 | Y13: 5 | Z13: 2 | AA13: 5 | AB13: 5 | AC13: 5 | AD13: 5 | AE13: Standardization | AF13: Reference Implementation is missing | AG13: see above | AH13: None | AI13: https://build.fillout.com/editor/jmGtx5dRm2us/results?sessionId=a75278c1-c512-412a-b9f6-3c716831b733 | AJ13: b1f87f15841c1a16248c1734275a1b0a | AK13: 39eb7965e6f03af232992599963d1dc7
A14: ebe015f1-a5ac-456a-9004-4c4b34f3f244 | B14: Tue Feb 03 2026 09:37:00 GMT+0100 (hora estándar de Europa central) | C14: Tue Feb 03 2026 09:15:00 GMT+0100 (hora estándar de Europa central) | D14: finished | E14: Ending | F14: 2 | G14: Yes | H14: Yes | I14: No | J14: Few | K14: No | L14: 3 | M14: 1 | N14: 4 | O14: 4 | P14: 4 | Q14: 2 | R14: 2 | S14: 1 | T14: 2 | U14: 1 | V14: 1 | W14: 2 | X14: 1 | Y14: 1 | Z14: 1 | AA14: 1 | AB14: 1 | AC14: 1 | AD14: 1 | AE14: None | AF14: I'm sorry for the negative answers. The SRA does contain very little (if any) domain-specific, that is, requirements engineering specific, components. The SRA could be applied to any text processing task, making it not useful for a requirements engineering tool developer. These generic architectures for NLP already exist (implicitly), see e.g. https://dkpro.github.io/ https://www.nltk.org/ | AG14: IMO, the architecture needs to be less generic and lower the abstraction level to requirements engineering concepts to be of use. | AH14: None | AI14: https://build.fillout.com/editor/jmGtx5dRm2us/results?sessionId=ebe015f1-a5ac-456a-9004-4c4b34f3f244 | AJ14: 3c006a3576fbc0954dc2db5414f4a467
A15: 7df9f735-92fc-4971-a6a3-36a4134eb074 | B15: Tue Feb 03 2026 02:53:00 GMT+0100 (hora estándar de Europa central) | C15: Tue Feb 03 2026 02:05:00 GMT+0100 (hora estándar de Europa central) | D15: finished | E15: Ending | F15: 2 | G15: Yes | H15: Yes | I15: No | J15: None | K15: Yes | L15: 5 | M15: 5 | N15: 3 | O15: 5 | P15: 4 | Q15: 4 | R15: 4 | S15: 5 | T15: 5 | U15: 5 | V15: 3 | W15: 5 | X15: 5 | Y15: 4 | Z15: 2 | AA15: 6 | AB15: 2 | AC15: 5 | AD15: 3 | AE15: I don't perceive any additional benefits beyond what has already been discussed. | AF15: Beyond what has been discussed, I’d like to highlight a few critical engineering and human factors: - Low Entry Barrier: A mature SRA should ideally be installable with a single command. It needs a compelling running example that showcases its core strengths and features immediately. - Documentation & Guardrails: Comprehensive API documentation is a must. More importantly, the SRA should explicitly define its 'non-goals' or anti-patterns—what it does not support or recommend. This prevents developers from wasting effort on ill-suited attempts. - Inherent Costs: We must acknowledge the learning curve and the higher initial setup cost compared to 'freestyle' development. Furthermore, architectural abstraction often makes debugging more challenging. | AH15: None | AI15: https://build.fillout.com/editor/jmGtx5dRm2us/results?sessionId=7df9f735-92fc-4971-a6a3-36a4134eb074 | AJ15: 15018a4a3e8496b90f5c5bb3e179f383
A16: a5641a6f-1416-4e91-8b6c-71eb9b0a2159 | B16: Mon Feb 02 2026 21:28:00 GMT+0100 (hora estándar de Europa central) | C16: Mon Feb 02 2026 20:56:00 GMT+0100 (hora estándar de Europa central) | D16: finished | E16: Ending | F16: 4 | G16: Yes | H16: Yes | I16: No | J16: None | K16: No | L16: 3 | M16: 4 | N16: 4 | O16: 5 | P16: 6 | Q16: 3 | R16: 5 | S16: 5 | T16: 5 | U16: 5 | V16: 6 | W16: 5 | X16: 4 | Y16: 6 | Z16: 1 | AA16: 6 | AB16: 5 | AC16: 6 | AD16: 6 | AE16: Most, like sustainability etc. have been mentioned. I don't think I can think of any other benefits. | AF16: I think interpretation what it means exactly will only be clear over time once people have used the SRA. I think using it as the authors intended is not 100% possible. | AG16: I think a standardisation can definitely reduce duplication of effort. I think the SRA needs more practical examples to be easier to understand. | AH16: None | AI16: https://build.fillout.com/editor/jmGtx5dRm2us/results?sessionId=a5641a6f-1416-4e91-8b6c-71eb9b0a2159 | AJ16: ff98f630f2d71112c15e926b4e220f02
A17: 05f738e6-6a48-411c-8e6f-aeaa3c4b1aa5 | B17: Mon Feb 02 2026 10:58:00 GMT+0100 (hora estándar de Europa central) | C17: Mon Feb 02 2026 10:51:00 GMT+0100 (hora estándar de Europa central) | D17: finished | E17: Ending | F17: 1 | G17: Yes | H17: Yes | I17: No | J17: None | K17: No | L17: 4 | M17: 4 | N17: 4 | O17: 5 | P17: 5 | Q17: 4 | R17: 4 | S17: 5 | T17: 5 | U17: 5 | V17: 5 | W17: 5 | X17: 4 | Y17: 4 | Z17: 3 | AA17: 7 | AB17: 5 | AC17: 3 | AD17: 4 | AE17: NLP tools that adhere to the SRA present more explainability than those that don't. | AF17: Adhering to the SRA and reengineering existing tools can take time. Training may be necessary for new adopters. | AH17: None | AI17: https://build.fillout.com/editor/jmGtx5dRm2us/results?sessionId=05f738e6-6a48-411c-8e6f-aeaa3c4b1aa5 | AJ17: a1699c34d1e61abae41a913867efe44a
A18: 273f2f5c-31f3-4209-8278-49d43dfb8f43 | B18: Mon Feb 02 2026 10:47:00 GMT+0100 (hora estándar de Europa central) | C18: Mon Feb 02 2026 10:26:00 GMT+0100 (hora estándar de Europa central) | D18: finished | E18: Ending | F18: 2 | G18: Yes | H18: Yes | I18: No | J18: Few | K18: Yes | L18: 2 | M18: 4 | N18: 2 | O18: 2 | P18: 3 | Q18: 2 | R18: 3 | S18: 4 | T18: 4 | U18: 6 | V18: 6 | W18: 5 | X18: 4 | Y18: 4 | Z18: 1 | AA18: 6 | AB18: 4 | AC18: 6 | AD18: 3 | AE18: I believe that having an SRA for NLP4RE tools would also help the community better understand the complexity of the software we build. Research tools often involve underlying complexity that is not made explicit; however, an SRA can clearly reveal this complexity. In particular, it would allow us to assess how challenging it would be to transition a tool from a research prototype to an industrial setting, and to compare it with successful cases that have already applied the SRA. | AF18: I believe the SRA itself would benefit from a clear, concrete example of use involving a specific set of NLP4RE tools. Although the description document explains the main components and the service view of the SRA to some extent, the overall flow between applying the SRA and conceiving the intended tool remains unclear. At this stage, adoption is likely to be challenging if the benefits are not explicitly linked to measurable outcomes. For example, demonstrating that the SRA reduces integration effort by 80-90% (or even eliminates it), or that it increases system understandability by a comparable margin, would make its value more tangible. Such results and evidence-based statements are missing, yet they are essential to properly assess the promise of the SRA for implemented software (basically answering, why should I use the SRA?). | AG18: As mentioned previously, the proposal would benefit from a clear end-to-end example demonstrating the use of the SRA. In addition, I believe enriching the package, service, and pipeline views with an explicit goal-oriented perspective would further strengthen the SRA. This would make the intended goals of adopting the SRA; and of the underlying system itself; more explicit, thereby improving clarity, traceability, and overall understanding. | AH18: None | AI18: https://build.fillout.com/editor/jmGtx5dRm2us/results?sessionId=273f2f5c-31f3-4209-8278-49d43dfb8f43 | AJ18: 3f8cbb6a92073e62c6e336ae8d228981
A19: eaad440e-5ada-4730-9f39-e1aa98d9d29d | B19: Wed Jan 28 2026 13:26:00 GMT+0100 (hora estándar de Europa central) | C19: Tue Jan 27 2026 15:53:00 GMT+0100 (hora estándar de Europa central) | D19: finished | E19: Ending | F19: 2 | G19: Yes | H19: Yes | I19: No | J19: None | K19: No | L19: 6 | M19: 6 | N19: 7 | O19: 7 | P19: 6 | Q19: 6 | R19: 4 | S19: 6 | T19: 5 | U19: 5 | V19: 6 | W19: 7 | X19: 7 | Y19: 7 | Z19: 5 | AA19: 6 | AB19: 6 | AC19: 7 | AD19: 6 | AE19: Scalability. In my opinion, the SRA makes it easy to scale out model serving (e.g., by adding more instances) | AF19: None about the SRA itself. | AG19: I really like this SRA, but sometimes, a monolith that just solves the problem is better than a decoupled architecture that takes more time to set up. I wonder what project scale or timeline does the overhead of the SRA become a justified investment (learning to use it, implementation of it, integration with current solutions)? | AH19: None | AI19: https://build.fillout.com/editor/jmGtx5dRm2us/results?sessionId=eaad440e-5ada-4730-9f39-e1aa98d9d29d | AJ19: e04062cc7745d247dd82a11ebc3eebb9
A20: a9b0d8f0-ea7b-446a-9a3d-c6d784a68b9a | B20: Mon Jan 26 2026 18:08:00 GMT+0100 (hora estándar de Europa central) | C20: Mon Jan 26 2026 17:59:00 GMT+0100 (hora estándar de Europa central) | D20: finished | E20: Ending | F20: 1 | G20: Yes | H20: No | I20: No | J20: Few | K20: Yes | L20: 5 | M20: 5 | N20: 5 | O20: 5 | P20: 5 | Q20: 5 | R20: 5 | S20: 5 | T20: 5 | U20: 5 | V20: 5 | W20: 5 | X20: 5 | Y20: 5 | Z20: 2 | AA20: 6 | AB20: 6 | AC20: 6 | AD20: 6 | AE20: modularity | AF20: The interfaces among the components should be well-defined. | AH20: None | AI20: https://build.fillout.com/editor/jmGtx5dRm2us/results?sessionId=a9b0d8f0-ea7b-446a-9a3d-c6d784a68b9a | AJ20: c12807df1ad67a07aee3f9092ddf3251
A21: ed6311f7-3989-44e4-ad0d-a8c648f0fd95 | B21: Mon Jan 26 2026 11:15:00 GMT+0100 (hora estándar de Europa central) | C21: Mon Jan 26 2026 10:14:00 GMT+0100 (hora estándar de Europa central) | D21: finished | E21: Ending | F21: 1 | G21: Yes | H21: Yes | I21: Yes | J21: Few | K21: No | L21: 7 | M21: 6 | N21: 6 | O21: 4 | P21: 7 | Q21: 5 | R21: 6 | S21: 5 | T21: 6 | U21: 6 | V21: 5 | W21: 6 | X21: 6 | Y21: 6 | Z21: 4 | AA21: 7 | AB21: 6 | AC21: 7 | AD21: 6 | AE21: Mostly covered | AF21: In the era of LLMs, I'm not sure whether providing a simple pipeline structure is solving the issues with reproducing and reusing components that heavily rely on LLMs. | AG21: The SRA very much looks like similar approaches for NLP tools (e.g. GATE) or for even more specialized tasks (e.g. TraceLab). In general I'm not sure what makes it specific for RE and which properties of RE tasks require it to be specialized. I see that the collection of tools and their adherence to it is beneficial for the RE community, but this would we able with other frameworks as well. | AH21: None | AI21: https://build.fillout.com/editor/jmGtx5dRm2us/results?sessionId=ed6311f7-3989-44e4-ad0d-a8c648f0fd95 | AJ21: b7f91ee0bd0712b0dd52f152ce988f66
A22: aab4b883-1788-4dec-ab86-6d44ffe60e65 | B22: Fri Jan 23 2026 14:01:00 GMT+0100 (hora estándar de Europa central) | C22: Fri Jan 23 2026 13:52:00 GMT+0100 (hora estándar de Europa central) | D22: finished | E22: Ending | F22: 1 | G22: Yes | H22: No | I22: No | J22: Few | K22: I don't know | L22: 5 | M22: 4 | N22: 4 | O22: 6 | P22: 5 | Q22: 4 | R22: 6 | S22: 7 | T22: 5 | U22: 5 | V22: 6 | W22: 6 | X22: 3 | Y22: 6 | Z22: 3 | AA22: 6 | AB22: 5 | AC22: 6 | AD22: 6 | AE22: To provide a common platform for the research community. | AF22: What can you reuse from other toolboxes (e.g., those from data mining or machine learning?) | AH22: None | AI22: https://build.fillout.com/editor/jmGtx5dRm2us/results?sessionId=aab4b883-1788-4dec-ab86-6d44ffe60e65 | AJ22: 39eb7965e6f03af232992599963d1dc7

Sheet Aux
A1: Perceived Ease of Use | D1: Usefulness | G1: Intention to Use | J1: Goal Fulfillment | M1: Demographics
A2: Question | B2: Score | D2: Question | E2: Score | G2: Question | H2: Score | J2: Question | K2: Score | M2: Question | N2: Score
A3: =IFERROR(__xludf.DUMMYFUNCTION("ARRAYFORMULA( QUERY( { FLATTEN(IF(Results!L2:Q22<>"""", Results!L1:Q1, )), FLATTEN(Results!L2:Q22) }, ""where Col2 is not null"", 0 ) ) "),"Learning to apply the SRA would be easy for me.") -> Learning to apply the SRA would be easy for me. | B3: =IFERROR(__xludf.DUMMYFUNCTION("""COMPUTED_VALUE"""),5.0) -> 5 | D3: =IFERROR(__xludf.DUMMYFUNCTION("ARRAYFORMULA( QUERY( { FLATTEN(IF(Results!R2:W22<>"""", Results!R1:W1, )), FLATTEN(Results!R2:W22) }, ""where Col2 is not null"", 0 ) ) "),"Using the SRA for developing a new NLP4RE tool would enable me to accomplish tasks more quickly.") -> Using the SRA for developing a new NLP4RE tool would enable me to accomplish tasks more quickly. | E3: =IFERROR(__xludf.DUMMYFUNCTION("""COMPUTED_VALUE"""),6.0) -> 6 | G3: =IFERROR(__xludf.DUMMYFUNCTION("ARRAYFORMULA( QUERY( { FLATTEN(IF(Results!X2:Z22<>"""", Results!X1:Z1, )), FLATTEN(Results!X2:Z22) }, ""where Col2 is not null"", 0 ) ) "),"I intend to use the SRA when developing an NLP4RE tool in the future.") -> I intend to use the SRA when developing an NLP4RE tool in the future. | H3: =IFERROR(__xludf.DUMMYFUNCTION("""COMPUTED_VALUE"""),4.0) -> 4 | J3: =IFERROR(__xludf.DUMMYFUNCTION("ARRAYFORMULA( QUERY( { FLATTEN(IF(Results!AA2:AD22<>"""", Results!AA1:AD1, )), FLATTEN(Results!AA2:AD22) }, ""where Col2 is not null"", 0 ) ) "),"It will cost less effort to re-use components from NLP4RE tools that adhere to the SRA than from comparable NLP4RE tools not adhering to it.") -> It will cost less effort to re-use components from NLP4RE tools that adhere to the SRA than from comparable NLP4RE tools not adhering to it. | K3: =IFERROR(__xludf.DUMMYFUNCTION("""COMPUTED_VALUE"""),7.0) -> 7 | M3: =IFERROR(__xludf.DUMMYFUNCTION("ARRAYFORMULA( QUERY( { FLATTEN(IF(Results!G2:G22<>"""", Results!G1, )), FLATTEN(Results!G2:G22) }, ""where Col2 is not null"", 0 ) ) "),"Have you been involved in the design of an NLP4RE tool?") -> Have you been involved in the design of an NLP4RE tool? | N3: =IFERROR(__xludf.DUMMYFUNCTION("""COMPUTED_VALUE"""),"Yes") -> Yes
A4: =IFERROR(__xludf.DUMMYFUNCTION("""COMPUTED_VALUE"""),"I would find it easy to get the information I need out of the SRA.") -> I would find it easy to get the information I need out of the SRA. | B4: =IFERROR(__xludf.DUMMYFUNCTION("""COMPUTED_VALUE"""),4.0) -> 4 | D4: =IFERROR(__xludf.DUMMYFUNCTION("""COMPUTED_VALUE"""),"Using the SRA would improve my performance when developing an NLP4RE tool.") -> Using the SRA would improve my performance when developing an NLP4RE tool. | E4: =IFERROR(__xludf.DUMMYFUNCTION("""COMPUTED_VALUE"""),5.0) -> 5 | G4: =IFERROR(__xludf.DUMMYFUNCTION("""COMPUTED_VALUE"""),"I intend to recommend colleagues, students, or others to use the SRA when developing a new NLP4RE tool.") -> I intend to recommend colleagues, students, or others to use the SRA when developing a new NLP4RE tool. | H4: =IFERROR(__xludf.DUMMYFUNCTION("""COMPUTED_VALUE"""),4.0) -> 4 | J4: =IFERROR(__xludf.DUMMYFUNCTION("""COMPUTED_VALUE"""),"An NLP4RE tool that adheres to the SRA is applicable to more use cases (e.g., different types of input documents) than comparable NLP4RE tools that do not adhere to it.") -> An NLP4RE tool that adheres to the SRA is applicable to more use cases (e.g., different types of input documents) than comparable NLP4RE tools that do not adhere to it. | K4: =IFERROR(__xludf.DUMMYFUNCTION("""COMPUTED_VALUE"""),7.0) -> 7 | M4: =IFERROR(__xludf.DUMMYFUNCTION("""COMPUTED_VALUE"""),"Have you been involved in the design of an NLP4RE tool?") -> Have you been involved in the design of an NLP4RE tool? | N4: =IFERROR(__xludf.DUMMYFUNCTION("""COMPUTED_VALUE"""),"Yes") -> Yes
A5: =IFERROR(__xludf.DUMMYFUNCTION("""COMPUTED_VALUE"""),"My interaction with the SRA would be clear and understandable.") -> My interaction with the SRA would be clear and understandable. | B5: =IFERROR(__xludf.DUMMYFUNCTION("""COMPUTED_VALUE"""),6.0) -> 6 | D5: =IFERROR(__xludf.DUMMYFUNCTION("""COMPUTED_VALUE"""),"Using the SRA when developing a new NLP4RE tool would increase my productivity.") -> Using the SRA when developing a new NLP4RE tool would increase my productivity. | E5: =IFERROR(__xludf.DUMMYFUNCTION("""COMPUTED_VALUE"""),5.0) -> 5 | G5: =IFERROR(__xludf.DUMMYFUNCTION("""COMPUTED_VALUE"""),"I intend to re-implement an existing NLP4RE tool using the SRA.") -> I intend to re-implement an existing NLP4RE tool using the SRA. | H5: =IFERROR(__xludf.DUMMYFUNCTION("""COMPUTED_VALUE"""),5.0) -> 5 | J5: =IFERROR(__xludf.DUMMYFUNCTION("""COMPUTED_VALUE"""),"An NLP4RE tool that adheres to the SRA is easier to compare with other tools that perform a similar task (e.g., requirements classification), than comparable NLP4RE tools that do not adhere to it.") -> An NLP4RE tool that adheres to the SRA is easier to compare with other tools that perform a similar task (e.g., requirements classification), than comparable NLP4RE tools that do not adhere to it. | K5: =IFERROR(__xludf.DUMMYFUNCTION("""COMPUTED_VALUE"""),7.0) -> 7 | M5: =IFERROR(__xludf.DUMMYFUNCTION("""COMPUTED_VALUE"""),"Have you been involved in the design of an NLP4RE tool?") -> Have you been involved in the design of an NLP4RE tool? | N5: =IFERROR(__xludf.DUMMYFUNCTION("""COMPUTED_VALUE"""),"Yes") -> Yes
A6: =IFERROR(__xludf.DUMMYFUNCTION("""COMPUTED_VALUE"""),"I would find SRA to be flexible to interact with.") -> I would find SRA to be flexible to interact with. | B6: =IFERROR(__xludf.DUMMYFUNCTION("""COMPUTED_VALUE"""),6.0) -> 6 | D6: =IFERROR(__xludf.DUMMYFUNCTION("""COMPUTED_VALUE"""),"Using the SRA would enhance my effectiveness when developing a new NLP4RE tool.") -> Using the SRA would enhance my effectiveness when developing a new NLP4RE tool. | E6: =IFERROR(__xludf.DUMMYFUNCTION("""COMPUTED_VALUE"""),5.0) -> 5 | G6: =IFERROR(__xludf.DUMMYFUNCTION("""COMPUTED_VALUE"""),"I intend to use the SRA when developing an NLP4RE tool in the future.") -> I intend to use the SRA when developing an NLP4RE tool in the future. | H6: =IFERROR(__xludf.DUMMYFUNCTION("""COMPUTED_VALUE"""),6.0) -> 6 | J6: =IFERROR(__xludf.DUMMYFUNCTION("""COMPUTED_VALUE"""),"An NLP4RE tool that adheres to the SRA is easier to maintain than comparable NLP4RE tools that do not adhere to it.") -> An NLP4RE tool that adheres to the SRA is easier to maintain than comparable NLP4RE tools that do not adhere to it. | K6: =IFERROR(__xludf.DUMMYFUNCTION("""COMPUTED_VALUE"""),7.0) -> 7 | M6: =IFERROR(__xludf.DUMMYFUNCTION("""COMPUTED_VALUE"""),"Have you been involved in the design of an NLP4RE tool?") -> Have you been involved in the design of an NLP4RE tool? | N6: =IFERROR(__xludf.DUMMYFUNCTION("""COMPUTED_VALUE"""),"Yes") -> Yes
A7: =IFERROR(__xludf.DUMMYFUNCTION("""COMPUTED_VALUE"""),"It would be easy for me to become skillful at using the SRA.") -> It would be easy for me to become skillful at using the SRA. | B7: =IFERROR(__xludf.DUMMYFUNCTION("""COMPUTED_VALUE"""),6.0) -> 6 | D7: =IFERROR(__xludf.DUMMYFUNCTION("""COMPUTED_VALUE"""),"Using the SRA would make it easier to develop a new NLP4RE tool.") -> Using the SRA would make it easier to develop a new NLP4RE tool. | E7: =IFERROR(__xludf.DUMMYFUNCTION("""COMPUTED_VALUE"""),5.0) -> 5 | G7: =IFERROR(__xludf.DUMMYFUNCTION("""COMPUTED_VALUE"""),"I intend to recommend colleagues, students, or others to use the SRA when developing a new NLP4RE tool.") -> I intend to recommend colleagues, students, or others to use the SRA when developing a new NLP4RE tool. | H7: =IFERROR(__xludf.DUMMYFUNCTION("""COMPUTED_VALUE"""),6.0) -> 6 | J7: =IFERROR(__xludf.DUMMYFUNCTION("""COMPUTED_VALUE"""),"It will cost less effort to re-use components from NLP4RE tools that adhere to the SRA than from comparable NLP4RE tools not adhering to it.") -> It will cost less effort to re-use components from NLP4RE tools that adhere to the SRA than from comparable NLP4RE tools not adhering to it. | K7: =IFERROR(__xludf.DUMMYFUNCTION("""COMPUTED_VALUE"""),4.0) -> 4 | M7: =IFERROR(__xludf.DUMMYFUNCTION("""COMPUTED_VALUE"""),"Have you been involved in the design of an NLP4RE tool?") -> Have you been involved in the design of an NLP4RE tool? | N7: =IFERROR(__xludf.DUMMYFUNCTION("""COMPUTED_VALUE"""),"Yes") -> Yes
A8: =IFERROR(__xludf.DUMMYFUNCTION("""COMPUTED_VALUE"""),"I would find the SRA easy to use.") -> I would find the SRA easy to use. | B8: =IFERROR(__xludf.DUMMYFUNCTION("""COMPUTED_VALUE"""),6.0) -> 6 | D8: =IFERROR(__xludf.DUMMYFUNCTION("""COMPUTED_VALUE"""),"I would find the SRA useful for developing a new NLP4RE tool.") -> I would find the SRA useful for developing a new NLP4RE tool. | E8: =IFERROR(__xludf.DUMMYFUNCTION("""COMPUTED_VALUE"""),6.0) -> 6 | G8: =IFERROR(__xludf.DUMMYFUNCTION("""COMPUTED_VALUE"""),"I intend to re-implement an existing NLP4RE tool using the SRA.") -> I intend to re-implement an existing NLP4RE tool using the SRA. | H8: =IFERROR(__xludf.DUMMYFUNCTION("""COMPUTED_VALUE"""),5.0) -> 5 | J8: =IFERROR(__xludf.DUMMYFUNCTION("""COMPUTED_VALUE"""),"An NLP4RE tool that adheres to the SRA is applicable to more use cases (e.g., different types of input documents) than comparable NLP4RE tools that do not adhere to it.") -> An NLP4RE tool that adheres to the SRA is applicable to more use cases (e.g., different types of input documents) than comparable NLP4RE tools that do not adhere to it. | K8: =IFERROR(__xludf.DUMMYFUNCTION("""COMPUTED_VALUE"""),4.0) -> 4 | M8: =IFERROR(__xludf.DUMMYFUNCTION("""COMPUTED_VALUE"""),"Have you been involved in the design of an NLP4RE tool?") -> Have you been involved in the design of an NLP4RE tool? | N8: =IFERROR(__xludf.DUMMYFUNCTION("""COMPUTED_VALUE"""),"Yes") -> Yes
A9: =IFERROR(__xludf.DUMMYFUNCTION("""COMPUTED_VALUE"""),"Learning to apply the SRA would be easy for me.") -> Learning to apply the SRA would be easy for me. | B9: =IFERROR(__xludf.DUMMYFUNCTION("""COMPUTED_VALUE"""),4.0) -> 4 | D9: =IFERROR(__xludf.DUMMYFUNCTION("""COMPUTED_VALUE"""),"Using the SRA for developing a new NLP4RE tool would enable me to accomplish tasks more quickly.") -> Using the SRA for developing a new NLP4RE tool would enable me to accomplish tasks more quickly. | E9: =IFERROR(__xludf.DUMMYFUNCTION("""COMPUTED_VALUE"""),6.0) -> 6 | G9: =IFERROR(__xludf.DUMMYFUNCTION("""COMPUTED_VALUE"""),"I intend to use the SRA when developing an NLP4RE tool in the future.") -> I intend to use the SRA when developing an NLP4RE tool in the future. | H9: =IFERROR(__xludf.DUMMYFUNCTION("""COMPUTED_VALUE"""),5.0) -> 5 | J9: =IFERROR(__xludf.DUMMYFUNCTION("""COMPUTED_VALUE"""),"An NLP4RE tool that adheres to the SRA is easier to compare with other tools that perform a similar task (e.g., requirements classification), than comparable NLP4RE tools that do not adhere to it.") -> An NLP4RE tool that adheres to the SRA is easier to compare with other tools that perform a similar task (e.g., requirements classification), than comparable NLP4RE tools that do not adhere to it. | K9: =IFERROR(__xludf.DUMMYFUNCTION("""COMPUTED_VALUE"""),6.0) -> 6 | M9: =IFERROR(__xludf.DUMMYFUNCTION("""COMPUTED_VALUE"""),"Have you been involved in the design of an NLP4RE tool?") -> Have you been involved in the design of an NLP4RE tool? | N9: =IFERROR(__xludf.DUMMYFUNCTION("""COMPUTED_VALUE"""),"Yes") -> Yes
A10: =IFERROR(__xludf.DUMMYFUNCTION("""COMPUTED_VALUE"""),"I would find it easy to get the information I need out of the SRA.") -> I would find it easy to get the information I need out of the SRA. | B10: =IFERROR(__xludf.DUMMYFUNCTION("""COMPUTED_VALUE"""),6.0) -> 6 | D10: =IFERROR(__xludf.DUMMYFUNCTION("""COMPUTED_VALUE"""),"Using the SRA would improve my performance when developing an NLP4RE tool.") -> Using the SRA would improve my performance when developing an NLP4RE tool. | E10: =IFERROR(__xludf.DUMMYFUNCTION("""COMPUTED_VALUE"""),6.0) -> 6 | G10: =IFERROR(__xludf.DUMMYFUNCTION("""COMPUTED_VALUE"""),"I intend to recommend colleagues, students, or others to use the SRA when developing a new NLP4RE tool.") -> I intend to recommend colleagues, students, or others to use the SRA when developing a new NLP4RE tool. | H10: =IFERROR(__xludf.DUMMYFUNCTION("""COMPUTED_VALUE"""),4.0) -> 4 | J10: =IFERROR(__xludf.DUMMYFUNCTION("""COMPUTED_VALUE"""),"An NLP4RE tool that adheres to the SRA is easier to maintain than comparable NLP4RE tools that do not adhere to it.") -> An NLP4RE tool that adheres to the SRA is easier to maintain than comparable NLP4RE tools that do not adhere to it. | K10: =IFERROR(__xludf.DUMMYFUNCTION("""COMPUTED_VALUE"""),5.0) -> 5 | M10: =IFERROR(__xludf.DUMMYFUNCTION("""COMPUTED_VALUE"""),"Have you been involved in the design of an NLP4RE tool?") -> Have you been involved in the design of an NLP4RE tool? | N10: =IFERROR(__xludf.DUMMYFUNCTION("""COMPUTED_VALUE"""),"Yes") -> Yes
A11: =IFERROR(__xludf.DUMMYFUNCTION("""COMPUTED_VALUE"""),"My interaction with the SRA would be clear and understandable.") -> My interaction with the SRA would be clear and understandable. | B11: =IFERROR(__xludf.DUMMYFUNCTION("""COMPUTED_VALUE"""),6.0) -> 6 | D11: =IFERROR(__xludf.DUMMYFUNCTION("""COMPUTED_VALUE"""),"Using the SRA when developing a new NLP4RE tool would increase my productivity.") -> Using the SRA when developing a new NLP4RE tool would increase my productivity. | E11: =IFERROR(__xludf.DUMMYFUNCTION("""COMPUTED_VALUE"""),6.0) -> 6 | G11: =IFERROR(__xludf.DUMMYFUNCTION("""COMPUTED_VALUE"""),"I intend to re-implement an existing NLP4RE tool using the SRA.") -> I intend to re-implement an existing NLP4RE tool using the SRA. | H11: =IFERROR(__xludf.DUMMYFUNCTION("""COMPUTED_VALUE"""),4.0) -> 4 | J11: =IFERROR(__xludf.DUMMYFUNCTION("""COMPUTED_VALUE"""),"It will cost less effort to re-use components from NLP4RE tools that adhere to the SRA than from comparable NLP4RE tools not adhering to it.") -> It will cost less effort to re-use components from NLP4RE tools that adhere to the SRA than from comparable NLP4RE tools not adhering to it. | K11: =IFERROR(__xludf.DUMMYFUNCTION("""COMPUTED_VALUE"""),5.0) -> 5 | M11: =IFERROR(__xludf.DUMMYFUNCTION("""COMPUTED_VALUE"""),"Have you been involved in the design of an NLP4RE tool?") -> Have you been involved in the design of an NLP4RE tool? | N11: =IFERROR(__xludf.DUMMYFUNCTION("""COMPUTED_VALUE"""),"Yes") -> Yes
A12: =IFERROR(__xludf.DUMMYFUNCTION("""COMPUTED_VALUE"""),"I would find SRA to be flexible to interact with.") -> I would find SRA to be flexible to interact with. | B12: =IFERROR(__xludf.DUMMYFUNCTION("""COMPUTED_VALUE"""),6.0) -> 6 | D12: =IFERROR(__xludf.DUMMYFUNCTION("""COMPUTED_VALUE"""),"Using the SRA would enhance my effectiveness when developing a new NLP4RE tool.") -> Using the SRA would enhance my effectiveness when developing a new NLP4RE tool. | E12: =IFERROR(__xludf.DUMMYFUNCTION("""COMPUTED_VALUE"""),6.0) -> 6 | G12: =IFERROR(__xludf.DUMMYFUNCTION("""COMPUTED_VALUE"""),"I intend to use the SRA when developing an NLP4RE tool in the future.") -> I intend to use the SRA when developing an NLP4RE tool in the future. | H12: =IFERROR(__xludf.DUMMYFUNCTION("""COMPUTED_VALUE"""),5.0) -> 5 | J12: =IFERROR(__xludf.DUMMYFUNCTION("""COMPUTED_VALUE"""),"An NLP4RE tool that adheres to the SRA is applicable to more use cases (e.g., different types of input documents) than comparable NLP4RE tools that do not adhere to it.") -> An NLP4RE tool that adheres to the SRA is applicable to more use cases (e.g., different types of input documents) than comparable NLP4RE tools that do not adhere to it. | K12: =IFERROR(__xludf.DUMMYFUNCTION("""COMPUTED_VALUE"""),4.0) -> 4 | M12: =IFERROR(__xludf.DUMMYFUNCTION("""COMPUTED_VALUE"""),"Have you been involved in the design of an NLP4RE tool?") -> Have you been involved in the design of an NLP4RE tool? | N12: =IFERROR(__xludf.DUMMYFUNCTION("""COMPUTED_VALUE"""),"Yes") -> Yes
A13: =IFERROR(__xludf.DUMMYFUNCTION("""COMPUTED_VALUE"""),"It would be easy for me to become skillful at using the SRA.") -> It would be easy for me to become skillful at using the SRA. | B13: =IFERROR(__xludf.DUMMYFUNCTION("""COMPUTED_VALUE"""),4.0) -> 4 | D13: =IFERROR(__xludf.DUMMYFUNCTION("""COMPUTED_VALUE"""),"Using the SRA would make it easier to develop a new NLP4RE tool.") -> Using the SRA would make it easier to develop a new NLP4RE tool. | E13: =IFERROR(__xludf.DUMMYFUNCTION("""COMPUTED_VALUE"""),6.0) -> 6 | G13: =IFERROR(__xludf.DUMMYFUNCTION("""COMPUTED_VALUE"""),"I intend to recommend colleagues, students, or others to use the SRA when developing a new NLP4RE tool.") -> I intend to recommend colleagues, students, or others to use the SRA when developing a new NLP4RE tool. | H13: =IFERROR(__xludf.DUMMYFUNCTION("""COMPUTED_VALUE"""),5.0) -> 5 | J13: =IFERROR(__xludf.DUMMYFUNCTION("""COMPUTED_VALUE"""),"An NLP4RE tool that adheres to the SRA is easier to compare with other tools that perform a similar task (e.g., requirements classification), than comparable NLP4RE tools that do not adhere to it.") -> An NLP4RE tool that adheres to the SRA is easier to compare with other tools that perform a similar task (e.g., requirements classification), than comparable NLP4RE tools that do not adhere to it. | K13: =IFERROR(__xludf.DUMMYFUNCTION("""COMPUTED_VALUE"""),6.0) -> 6 | M13: =IFERROR(__xludf.DUMMYFUNCTION("""COMPUTED_VALUE"""),"Have you been involved in the design of an NLP4RE tool?") -> Have you been involved in the design of an NLP4RE tool? | N13: =IFERROR(__xludf.DUMMYFUNCTION("""COMPUTED_VALUE"""),"Yes") -> Yes
A14: =IFERROR(__xludf.DUMMYFUNCTION("""COMPUTED_VALUE"""),"I would find the SRA easy to use.") -> I would find the SRA easy to use. | B14: =IFERROR(__xludf.DUMMYFUNCTION("""COMPUTED_VALUE"""),6.0) -> 6 | D14: =IFERROR(__xludf.DUMMYFUNCTION("""COMPUTED_VALUE"""),"I would find the SRA useful for developing a new NLP4RE tool.") -> I would find the SRA useful for developing a new NLP4RE tool. | E14: =IFERROR(__xludf.DUMMYFUNCTION("""COMPUTED_VALUE"""),6.0) -> 6 | G14: =IFERROR(__xludf.DUMMYFUNCTION("""COMPUTED_VALUE"""),"I intend to re-implement an existing NLP4RE tool using the SRA.") -> I intend to re-implement an existing NLP4RE tool using the SRA. | H14: =IFERROR(__xludf.DUMMYFUNCTION("""COMPUTED_VALUE"""),2.0) -> 2 | J14: =IFERROR(__xludf.DUMMYFUNCTION("""COMPUTED_VALUE"""),"An NLP4RE tool that adheres to the SRA is easier to maintain than comparable NLP4RE tools that do not adhere to it.") -> An NLP4RE tool that adheres to the SRA is easier to maintain than comparable NLP4RE tools that do not adhere to it. | K14: =IFERROR(__xludf.DUMMYFUNCTION("""COMPUTED_VALUE"""),4.0) -> 4 | M14: =IFERROR(__xludf.DUMMYFUNCTION("""COMPUTED_VALUE"""),"Have you been involved in the design of an NLP4RE tool?") -> Have you been involved in the design of an NLP4RE tool? | N14: =IFERROR(__xludf.DUMMYFUNCTION("""COMPUTED_VALUE"""),"Yes") -> Yes
A15: =IFERROR(__xludf.DUMMYFUNCTION("""COMPUTED_VALUE"""),"Learning to apply the SRA would be easy for me.") -> Learning to apply the SRA would be easy for me. | B15: =IFERROR(__xludf.DUMMYFUNCTION("""COMPUTED_VALUE"""),4.0) -> 4 | D15: =IFERROR(__xludf.DUMMYFUNCTION("""COMPUTED_VALUE"""),"Using the SRA for developing a new NLP4RE tool would enable me to accomplish tasks more quickly.") -> Using the SRA for developing a new NLP4RE tool would enable me to accomplish tasks more quickly. | E15: =IFERROR(__xludf.DUMMYFUNCTION("""COMPUTED_VALUE"""),5.0) -> 5 | G15: =IFERROR(__xludf.DUMMYFUNCTION("""COMPUTED_VALUE"""),"I intend to use the SRA when developing an NLP4RE tool in the future.") -> I intend to use the SRA when developing an NLP4RE tool in the future. | H15: =IFERROR(__xludf.DUMMYFUNCTION("""COMPUTED_VALUE"""),5.0) -> 5 | J15: =IFERROR(__xludf.DUMMYFUNCTION("""COMPUTED_VALUE"""),"It will cost less effort to re-use components from NLP4RE tools that adhere to the SRA than from comparable NLP4RE tools not adhering to it.") -> It will cost less effort to re-use components from NLP4RE tools that adhere to the SRA than from comparable NLP4RE tools not adhering to it. | K15: =IFERROR(__xludf.DUMMYFUNCTION("""COMPUTED_VALUE"""),7.0) -> 7 | M15: =IFERROR(__xludf.DUMMYFUNCTION("""COMPUTED_VALUE"""),"Have you been involved in the design of an NLP4RE tool?") -> Have you been involved in the design of an NLP4RE tool? | N15: =IFERROR(__xludf.DUMMYFUNCTION("""COMPUTED_VALUE"""),"Yes") -> Yes
A16: =IFERROR(__xludf.DUMMYFUNCTION("""COMPUTED_VALUE"""),"I would find it easy to get the information I need out of the SRA.") -> I would find it easy to get the information I need out of the SRA. | B16: =IFERROR(__xludf.DUMMYFUNCTION("""COMPUTED_VALUE"""),4.0) -> 4 | D16: =IFERROR(__xludf.DUMMYFUNCTION("""COMPUTED_VALUE"""),"Using the SRA would improve my performance when developing an NLP4RE tool.") -> Using the SRA would improve my performance when developing an NLP4RE tool. | E16: =IFERROR(__xludf.DUMMYFUNCTION("""COMPUTED_VALUE"""),4.0) -> 4 | G16: =IFERROR(__xludf.DUMMYFUNCTION("""COMPUTED_VALUE"""),"I intend to recommend colleagues, students, or others to use the SRA when developing a new NLP4RE tool.") -> I intend to recommend colleagues, students, or others to use the SRA when developing a new NLP4RE tool. | H16: =IFERROR(__xludf.DUMMYFUNCTION("""COMPUTED_VALUE"""),4.0) -> 4 | J16: =IFERROR(__xludf.DUMMYFUNCTION("""COMPUTED_VALUE"""),"An NLP4RE tool that adheres to the SRA is applicable to more use cases (e.g., different types of input documents) than comparable NLP4RE tools that do not adhere to it.") -> An NLP4RE tool that adheres to the SRA is applicable to more use cases (e.g., different types of input documents) than comparable NLP4RE tools that do not adhere to it. | K16: =IFERROR(__xludf.DUMMYFUNCTION("""COMPUTED_VALUE"""),7.0) -> 7 | M16: =IFERROR(__xludf.DUMMYFUNCTION("""COMPUTED_VALUE"""),"Have you been involved in the design of an NLP4RE tool?") -> Have you been involved in the design of an NLP4RE tool? | N16: =IFERROR(__xludf.DUMMYFUNCTION("""COMPUTED_VALUE"""),"Yes") -> Yes
A17: =IFERROR(__xludf.DUMMYFUNCTION("""COMPUTED_VALUE"""),"My interaction with the SRA would be clear and understandable.") -> My interaction with the SRA would be clear and understandable. | B17: =IFERROR(__xludf.DUMMYFUNCTION("""COMPUTED_VALUE"""),4.0) -> 4 | D17: =IFERROR(__xludf.DUMMYFUNCTION("""COMPUTED_VALUE"""),"Using the SRA when developing a new NLP4RE tool would increase my productivity.") -> Using the SRA when developing a new NLP4RE tool would increase my productivity. | E17: =IFERROR(__xludf.DUMMYFUNCTION("""COMPUTED_VALUE"""),5.0) -> 5 | G17: =IFERROR(__xludf.DUMMYFUNCTION("""COMPUTED_VALUE"""),"I intend to re-implement an existing NLP4RE tool using the SRA.") -> I intend to re-implement an existing NLP4RE tool using the SRA. | H17: =IFERROR(__xludf.DUMMYFUNCTION("""COMPUTED_VALUE"""),2.0) -> 2 | J17: =IFERROR(__xludf.DUMMYFUNCTION("""COMPUTED_VALUE"""),"An NLP4RE tool that adheres to the SRA is easier to compare with other tools that perform a similar task (e.g., requirements classification), than comparable NLP4RE tools that do not adhere to it.") -> An NLP4RE tool that adheres to the SRA is easier to compare with other tools that perform a similar task (e.g., requirements classification), than comparable NLP4RE tools that do not adhere to it. | K17: =IFERROR(__xludf.DUMMYFUNCTION("""COMPUTED_VALUE"""),7.0) -> 7 | M17: =IFERROR(__xludf.DUMMYFUNCTION("""COMPUTED_VALUE"""),"Have you been involved in the design of an NLP4RE tool?") -> Have you been involved in the design of an NLP4RE tool? | N17: =IFERROR(__xludf.DUMMYFUNCTION("""COMPUTED_VALUE"""),"Yes") -> Yes
A18: =IFERROR(__xludf.DUMMYFUNCTION("""COMPUTED_VALUE"""),"I would find SRA to be flexible to interact with.") -> I would find SRA to be flexible to interact with. | B18: =IFERROR(__xludf.DUMMYFUNCTION("""COMPUTED_VALUE"""),4.0) -> 4 | D18: =IFERROR(__xludf.DUMMYFUNCTION("""COMPUTED_VALUE"""),"Using the SRA would enhance my effectiveness when developing a new NLP4RE tool.") -> Using the SRA would enhance my effectiveness when developing a new NLP4RE tool. | E18: =IFERROR(__xludf.DUMMYFUNCTION("""COMPUTED_VALUE"""),4.0) -> 4 | G18: =IFERROR(__xludf.DUMMYFUNCTION("""COMPUTED_VALUE"""),"I intend to use the SRA when developing an NLP4RE tool in the future.") -> I intend to use the SRA when developing an NLP4RE tool in the future. | H18: =IFERROR(__xludf.DUMMYFUNCTION("""COMPUTED_VALUE"""),4.0) -> 4 | J18: =IFERROR(__xludf.DUMMYFUNCTION("""COMPUTED_VALUE"""),"An NLP4RE tool that adheres to the SRA is easier to maintain than comparable NLP4RE tools that do not adhere to it.") -> An NLP4RE tool that adheres to the SRA is easier to maintain than comparable NLP4RE tools that do not adhere to it. | K18: =IFERROR(__xludf.DUMMYFUNCTION("""COMPUTED_VALUE"""),6.0) -> 6 | M18: =IFERROR(__xludf.DUMMYFUNCTION("""COMPUTED_VALUE"""),"Have you been involved in the design of an NLP4RE tool?") -> Have you been involved in the design of an NLP4RE tool? | N18: =IFERROR(__xludf.DUMMYFUNCTION("""COMPUTED_VALUE"""),"Yes") -> Yes
A19: =IFERROR(__xludf.DUMMYFUNCTION("""COMPUTED_VALUE"""),"It would be easy for me to become skillful at using the SRA.") -> It would be easy for me to become skillful at using the SRA. | B19: =IFERROR(__xludf.DUMMYFUNCTION("""COMPUTED_VALUE"""),4.0) -> 4 | D19: =IFERROR(__xludf.DUMMYFUNCTION("""COMPUTED_VALUE"""),"Using the SRA would make it easier to develop a new NLP4RE tool.") -> Using the SRA would make it easier to develop a new NLP4RE tool. | E19: =IFERROR(__xludf.DUMMYFUNCTION("""COMPUTED_VALUE"""),5.0) -> 5 | G19: =IFERROR(__xludf.DUMMYFUNCTION("""COMPUTED_VALUE"""),"I intend to recommend colleagues, students, or others to use the SRA when developing a new NLP4RE tool.") -> I intend to recommend colleagues, students, or others to use the SRA when developing a new NLP4RE tool. | H19: =IFERROR(__xludf.DUMMYFUNCTION("""COMPUTED_VALUE"""),4.0) -> 4 | J19: =IFERROR(__xludf.DUMMYFUNCTION("""COMPUTED_VALUE"""),"It will cost less effort to re-use components from NLP4RE tools that adhere to the SRA than from comparable NLP4RE tools not adhering to it.") -> It will cost less effort to re-use components from NLP4RE tools that adhere to the SRA than from comparable NLP4RE tools not adhering to it. | K19: =IFERROR(__xludf.DUMMYFUNCTION("""COMPUTED_VALUE"""),6.0) -> 6 | M19: =IFERROR(__xludf.DUMMYFUNCTION("""COMPUTED_VALUE"""),"Have you been involved in the design of an NLP4RE tool?") -> Have you been involved in the design of an NLP4RE tool? | N19: =IFERROR(__xludf.DUMMYFUNCTION("""COMPUTED_VALUE"""),"Yes") -> Yes
A20: =IFERROR(__xludf.DUMMYFUNCTION("""COMPUTED_VALUE"""),"I would find the SRA easy to use.") -> I would find the SRA easy to use. | B20: =IFERROR(__xludf.DUMMYFUNCTION("""COMPUTED_VALUE"""),4.0) -> 4 | D20: =IFERROR(__xludf.DUMMYFUNCTION("""COMPUTED_VALUE"""),"I would find the SRA useful for developing a new NLP4RE tool.") -> I would find the SRA useful for developing a new NLP4RE tool. | E20: =IFERROR(__xludf.DUMMYFUNCTION("""COMPUTED_VALUE"""),5.0) -> 5 | G20: =IFERROR(__xludf.DUMMYFUNCTION("""COMPUTED_VALUE"""),"I intend to re-implement an existing NLP4RE tool using the SRA.") -> I intend to re-implement an existing NLP4RE tool using the SRA. | H20: =IFERROR(__xludf.DUMMYFUNCTION("""COMPUTED_VALUE"""),1.0) -> 1 | J20: =IFERROR(__xludf.DUMMYFUNCTION("""COMPUTED_VALUE"""),"An NLP4RE tool that adheres to the SRA is applicable to more use cases (e.g., different types of input documents) than comparable NLP4RE tools that do not adhere to it.") -> An NLP4RE tool that adheres to the SRA is applicable to more use cases (e.g., different types of input documents) than comparable NLP4RE tools that do not adhere to it. | K20: =IFERROR(__xludf.DUMMYFUNCTION("""COMPUTED_VALUE"""),5.0) -> 5 | M20: =IFERROR(__xludf.DUMMYFUNCTION("""COMPUTED_VALUE"""),"Have you been involved in the design of an NLP4RE tool?") -> Have you been involved in the design of an NLP4RE tool? | N20: =IFERROR(__xludf.DUMMYFUNCTION("""COMPUTED_VALUE"""),"Yes") -> Yes
A21: =IFERROR(__xludf.DUMMYFUNCTION("""COMPUTED_VALUE"""),"Learning to apply the SRA would be easy for me.") -> Learning to apply the SRA would be easy for me. | B21: =IFERROR(__xludf.DUMMYFUNCTION("""COMPUTED_VALUE"""),5.0) -> 5 | D21: =IFERROR(__xludf.DUMMYFUNCTION("""COMPUTED_VALUE"""),"Using the SRA for developing a new NLP4RE tool would enable me to accomplish tasks more quickly.") -> Using the SRA for developing a new NLP4RE tool would enable me to accomplish tasks more quickly. | E21: =IFERROR(__xludf.DUMMYFUNCTION("""COMPUTED_VALUE"""),6.0) -> 6 | G21: =IFERROR(__xludf.DUMMYFUNCTION("""COMPUTED_VALUE"""),"I intend to use the SRA when developing an NLP4RE tool in the future.") -> I intend to use the SRA when developing an NLP4RE tool in the future. | H21: =IFERROR(__xludf.DUMMYFUNCTION("""COMPUTED_VALUE"""),5.0) -> 5 | J21: =IFERROR(__xludf.DUMMYFUNCTION("""COMPUTED_VALUE"""),"An NLP4RE tool that adheres to the SRA is easier to compare with other tools that perform a similar task (e.g., requirements classification), than comparable NLP4RE tools that do not adhere to it.") -> An NLP4RE tool that adheres to the SRA is easier to compare with other tools that perform a similar task (e.g., requirements classification), than comparable NLP4RE tools that do not adhere to it. | K21: =IFERROR(__xludf.DUMMYFUNCTION("""COMPUTED_VALUE"""),7.0) -> 7 | M21: =IFERROR(__xludf.DUMMYFUNCTION("""COMPUTED_VALUE"""),"Have you been involved in the design of an NLP4RE tool?") -> Have you been involved in the design of an NLP4RE tool? | N21: =IFERROR(__xludf.DUMMYFUNCTION("""COMPUTED_VALUE"""),"Yes") -> Yes
A22: =IFERROR(__xludf.DUMMYFUNCTION("""COMPUTED_VALUE"""),"I would find it easy to get the information I need out of the SRA.") -> I would find it easy to get the information I need out of the SRA. | B22: =IFERROR(__xludf.DUMMYFUNCTION("""COMPUTED_VALUE"""),3.0) -> 3 | D22: =IFERROR(__xludf.DUMMYFUNCTION("""COMPUTED_VALUE"""),"Using the SRA would improve my performance when developing an NLP4RE tool.") -> Using the SRA would improve my performance when developing an NLP4RE tool. | E22: =IFERROR(__xludf.DUMMYFUNCTION("""COMPUTED_VALUE"""),6.0) -> 6 | G22: =IFERROR(__xludf.DUMMYFUNCTION("""COMPUTED_VALUE"""),"I intend to recommend colleagues, students, or others to use the SRA when developing a new NLP4RE tool.") -> I intend to recommend colleagues, students, or others to use the SRA when developing a new NLP4RE tool. | H22: =IFERROR(__xludf.DUMMYFUNCTION("""COMPUTED_VALUE"""),6.0) -> 6 | J22: =IFERROR(__xludf.DUMMYFUNCTION("""COMPUTED_VALUE"""),"An NLP4RE tool that adheres to the SRA is easier to maintain than comparable NLP4RE tools that do not adhere to it.") -> An NLP4RE tool that adheres to the SRA is easier to maintain than comparable NLP4RE tools that do not adhere to it. | K22: =IFERROR(__xludf.DUMMYFUNCTION("""COMPUTED_VALUE"""),7.0) -> 7 | M22: =IFERROR(__xludf.DUMMYFUNCTION("""COMPUTED_VALUE"""),"Have you been involved in the design of an NLP4RE tool?") -> Have you been involved in the design of an NLP4RE tool? | N22: =IFERROR(__xludf.DUMMYFUNCTION("""COMPUTED_VALUE"""),"Yes") -> Yes
